Workbook

Sheet Agent_Summary
A1: Agent Performance Summary
A2: Source: Agent_Logs_Raw (agent_interaction_logs.csv), 400 interactions
A4: Agent | B4: Calls | C4: Avg Latency (ms) | D4: Avg Tokens | E4: Avg Rating | F4: Escalations | G4: Escalation %
A5: Adverse Event Triage Agent | B5: =COUNTIF(Agent_Logs_Raw!F2:F401,A5) -> 71 | C5: =ROUND(AVERAGEIF(Agent_Logs_Raw!F2:F401,A5,Agent_Logs_Raw!I2:I401),0) -> 1426 | D5: =ROUND(AVERAGEIF(Agent_Logs_Raw!F2:F401,A5,Agent_Logs_Raw!J2:J401),0) -> 3719 | E5: =ROUND(AVERAGEIF(Agent_Logs_Raw!F2:F401,A5,Agent_Logs_Raw!K2:K401),2) -> 4.08 | F5: =COUNTIFS(Agent_Logs_Raw!F2:F401,A5,Agent_Logs_Raw!L2:L401,TRUE()) -> 13 | G5: =ROUND(F5/B5*100,1) -> 18.3
A6: Compound Similarity Agent | B6: =COUNTIF(Agent_Logs_Raw!F2:F401,A6) -> 70 | C6: =ROUND(AVERAGEIF(Agent_Logs_Raw!F2:F401,A6,Agent_Logs_Raw!I2:I401),0) -> 1379 | D6: =ROUND(AVERAGEIF(Agent_Logs_Raw!F2:F401,A6,Agent_Logs_Raw!J2:J401),0) -> 3339 | E6: =ROUND(AVERAGEIF(Agent_Logs_Raw!F2:F401,A6,Agent_Logs_Raw!K2:K401),2) -> 4.1 | F6: =COUNTIFS(Agent_Logs_Raw!F2:F401,A6,Agent_Logs_Raw!L2:L401,TRUE()) -> 0 | G6: =ROUND(F6/B6*100,1) -> 0
A7: Literature & Document Research Agent | B7: =COUNTIF(Agent_Logs_Raw!F2:F401,A7) -> 64 | C7: =ROUND(AVERAGEIF(Agent_Logs_Raw!F2:F401,A7,Agent_Logs_Raw!I2:I401),0) -> 1572 | D7: =ROUND(AVERAGEIF(Agent_Logs_Raw!F2:F401,A7,Agent_Logs_Raw!J2:J401),0) -> 3194 | E7: =ROUND(AVERAGEIF(Agent_Logs_Raw!F2:F401,A7,Agent_Logs_Raw!K2:K401),2) -> 4.11 | F7: =COUNTIFS(Agent_Logs_Raw!F2:F401,A7,Agent_Logs_Raw!L2:L401,TRUE()) -> 0 | G7: =ROUND(F7/B7*100,1) -> 0
A8: Report Writer Agent | B8: =COUNTIF(Agent_Logs_Raw!F2:F401,A8) -> 62 | C8: =ROUND(AVERAGEIF(Agent_Logs_Raw!F2:F401,A8,Agent_Logs_Raw!I2:I401),0) -> 1480 | D8: =ROUND(AVERAGEIF(Agent_Logs_Raw!F2:F401,A8,Agent_Logs_Raw!J2:J401),0) -> 3671 | E8: =ROUND(AVERAGEIF(Agent_Logs_Raw!F2:F401,A8,Agent_Logs_Raw!K2:K401),2) -> 4.11 | F8: =COUNTIFS(Agent_Logs_Raw!F2:F401,A8,Agent_Logs_Raw!L2:L401,TRUE()) -> 0 | G8: =ROUND(F8/B8*100,1) -> 0
A9: Router / Planner Agent | B9: =COUNTIF(Agent_Logs_Raw!F2:F401,A9) -> 62 | C9: =ROUND(AVERAGEIF(Agent_Logs_Raw!F2:F401,A9,Agent_Logs_Raw!I2:I401),0) -> 1313 | D9: =ROUND(AVERAGEIF(Agent_Logs_Raw!F2:F401,A9,Agent_Logs_Raw!J2:J401),0) -> 3122 | E9: =ROUND(AVERAGEIF(Agent_Logs_Raw!F2:F401,A9,Agent_Logs_Raw!K2:K401),2) -> 4.19 | F9: =COUNTIFS(Agent_Logs_Raw!F2:F401,A9,Agent_Logs_Raw!L2:L401,TRUE()) -> 0 | G9: =ROUND(F9/B9*100,1) -> 0
A10: Trial Data Analyst Agent | B10: =COUNTIF(Agent_Logs_Raw!F2:F401,A10) -> 71 | C10: =ROUND(AVERAGEIF(Agent_Logs_Raw!F2:F401,A10,Agent_Logs_Raw!I2:I401),0) -> 1453 | D10: =ROUND(AVERAGEIF(Agent_Logs_Raw!F2:F401,A10,Agent_Logs_Raw!J2:J401),0) -> 3384 | E10: =ROUND(AVERAGEIF(Agent_Logs_Raw!F2:F401,A10,Agent_Logs_Raw!K2:K401),2) -> 4.3 | F10: =COUNTIFS(Agent_Logs_Raw!F2:F401,A10,Agent_Logs_Raw!L2:L401,TRUE()) -> 0 | G10: =ROUND(F10/B10*100,1) -> 0
A13: Tool Usage Summary
A14: Tool | B14: Calls | C14: Avg Latency (ms) | D14: Max Latency (ms)
A15: ae_severity_classifier_tool | B15: =COUNTIF(Agent_Logs_Raw!G2:G401,A15) -> 73 | C15: =ROUND(AVERAGEIF(Agent_Logs_Raw!G2:G401,A15,Agent_Logs_Raw!I2:I401),0) -> 1335 | D15: =_xlfn.MAXIFS(Agent_Logs_Raw!I2:I401,Agent_Logs_Raw!G2:G401,A15) -> 2681
A16: citation_formatter_tool | B16: =COUNTIF(Agent_Logs_Raw!G2:G401,A16) -> 47 | C16: =ROUND(AVERAGEIF(Agent_Logs_Raw!G2:G401,A16,Agent_Logs_Raw!I2:I401),0) -> 1312 | D16: =_xlfn.MAXIFS(Agent_Logs_Raw!I2:I401,Agent_Logs_Raw!G2:G401,A16) -> 2729
A17: compound_similarity_tool | B17: =COUNTIF(Agent_Logs_Raw!G2:G401,A17) -> 52 | C17: =ROUND(AVERAGEIF(Agent_Logs_Raw!G2:G401,A17,Agent_Logs_Raw!I2:I401),0) -> 1509 | D17: =_xlfn.MAXIFS(Agent_Logs_Raw!I2:I401,Agent_Logs_Raw!G2:G401,A17) -> 3433
A18: escalation_notifier_tool | B18: =COUNTIF(Agent_Logs_Raw!G2:G401,A18) -> 65 | C18: =ROUND(AVERAGEIF(Agent_Logs_Raw!G2:G401,A18,Agent_Logs_Raw!I2:I401),0) -> 1630 | D18: =_xlfn.MAXIFS(Agent_Logs_Raw!I2:I401,Agent_Logs_Raw!G2:G401,A18) -> 4166
A19: sql_query_tool | B19: =COUNTIF(Agent_Logs_Raw!G2:G401,A19) -> 58 | C19: =ROUND(AVERAGEIF(Agent_Logs_Raw!G2:G401,A19,Agent_Logs_Raw!I2:I401),0) -> 1430 | D19: =_xlfn.MAXIFS(Agent_Logs_Raw!I2:I401,Agent_Logs_Raw!G2:G401,A19) -> 2943
A20: statistics_tool | B20: =COUNTIF(Agent_Logs_Raw!G2:G401,A20) -> 54 | C20: =ROUND(AVERAGEIF(Agent_Logs_Raw!G2:G401,A20,Agent_Logs_Raw!I2:I401),0) -> 1403 | D20: =_xlfn.MAXIFS(Agent_Logs_Raw!I2:I401,Agent_Logs_Raw!G2:G401,A20) -> 2837
A21: vector_search_tool | B21: =COUNTIF(Agent_Logs_Raw!G2:G401,A21) -> 51 | C21: =ROUND(AVERAGEIF(Agent_Logs_Raw!G2:G401,A21,Agent_Logs_Raw!I2:I401),0) -> 1422 | D21: =_xlfn.MAXIFS(Agent_Logs_Raw!I2:I401,Agent_Logs_Raw!G2:G401,A21) -> 3498

Sheet Trial_AE_Summary
A1: Clinical Trial & Adverse Event Summary
A2: Sources: Trials_Raw (clinical_trials.csv), AE_Raw (adverse_events.csv), Sites_Raw (trial_sites.csv)
A4: Enrollment by Trial Phase
A5: Trial Phase | B5: # Trials | C5: Target Enrollment | D5: Actual Enrollment | E5: % Enrolled
A6: Phase I | B6: =COUNTIF(Trials_Raw!C2:C111,A6) -> 37 | C6: =SUMIF(Trials_Raw!C2:C111,A6,Trials_Raw!J2:J111) -> 11661 | D6: =SUMIF(Trials_Raw!C2:C111,A6,Trials_Raw!K2:K111) -> 8375 | E6: =ROUND(D6/C6*100,1) -> 71.8
A7: Phase II | B7: =COUNTIF(Trials_Raw!C2:C111,A7) -> 33 | C7: =SUMIF(Trials_Raw!C2:C111,A7,Trials_Raw!J2:J111) -> 10919 | D7: =SUMIF(Trials_Raw!C2:C111,A7,Trials_Raw!K2:K111) -> 8231 | E7: =ROUND(D7/C7*100,1) -> 75.4
A8: Phase III | B8: =COUNTIF(Trials_Raw!C2:C111,A8) -> 31 | C8: =SUMIF(Trials_Raw!C2:C111,A8,Trials_Raw!J2:J111) -> 9545 | D8: =SUMIF(Trials_Raw!C2:C111,A8,Trials_Raw!K2:K111) -> 6283 | E8: =ROUND(D8/C8*100,1) -> 65.8
A9: Phase IV | B9: =COUNTIF(Trials_Raw!C2:C111,A9) -> 9 | C9: =SUMIF(Trials_Raw!C2:C111,A9,Trials_Raw!J2:J111) -> 2809 | D9: =SUMIF(Trials_Raw!C2:C111,A9,Trials_Raw!K2:K111) -> 2393 | E9: =ROUND(D9/C9*100,1) -> 85.2
A12: Trials by Status
A13: Status | B13: # Trials
A14: Active, not recruiting | B14: =COUNTIF(Trials_Raw!I2:I111,A14) -> 29
A15: Completed | B15: =COUNTIF(Trials_Raw!I2:I111,A15) -> 39
A16: Recruiting | B16: =COUNTIF(Trials_Raw!I2:I111,A16) -> 27
A17: Suspended | B17: =COUNTIF(Trials_Raw!I2:I111,A17) -> 6
A18: Terminated | B18: =COUNTIF(Trials_Raw!I2:I111,A18) -> 9
A21: Adverse Events by Severity
A22: Severity | B22: # Events | C22: # Serious
A23: Mild | B23: =COUNTIF(AE_Raw!F2:F501,A23) -> 0 | C23: =COUNTIFS(AE_Raw!F2:F501,A23,AE_Raw!G2:G501,"Serious") -> 0
A24: Moderate | B24: =COUNTIF(AE_Raw!F2:F501,A24) -> 0 | C24: =COUNTIFS(AE_Raw!F2:F501,A24,AE_Raw!G2:G501,"Serious") -> 0
A25: Severe | B25: =COUNTIF(AE_Raw!F2:F501,A25) -> 0 | C25: =COUNTIFS(AE_Raw!F2:F501,A25,AE_Raw!G2:G501,"Serious") -> 0
A28: Sites & Enrollment by Country
A29: Country | B29: # Sites | C29: Enrollment Count | D29: # Active Sites
A30: Australia | B30: =COUNTIF(Sites_Raw!C2:C376,A30) -> 0 | C30: =SUMIF(Sites_Raw!C2:C376,A30,Sites_Raw!F2:F376) -> 0 | D30: =COUNTIFS(Sites_Raw!C2:C376,A30,Sites_Raw!G2:G376,"Active") -> 0
A31: Brazil | B31: =COUNTIF(Sites_Raw!C2:C376,A31) -> 0 | C31: =SUMIF(Sites_Raw!C2:C376,A31,Sites_Raw!F2:F376) -> 0 | D31: =COUNTIFS(Sites_Raw!C2:C376,A31,Sites_Raw!G2:G376,"Active") -> 0
A32: Canada | B32: =COUNTIF(Sites_Raw!C2:C376,A32) -> 0 | C32: =SUMIF(Sites_Raw!C2:C376,A32,Sites_Raw!F2:F376) -> 0 | D32: =COUNTIFS(Sites_Raw!C2:C376,A32,Sites_Raw!G2:G376,"Active") -> 0
A33: Germany | B33: =COUNTIF(Sites_Raw!C2:C376,A33) -> 0 | C33: =SUMIF(Sites_Raw!C2:C376,A33,Sites_Raw!F2:F376) -> 0 | D33: =COUNTIFS(Sites_Raw!C2:C376,A33,Sites_Raw!G2:G376,"Active") -> 0
A34: India | B34: =COUNTIF(Sites_Raw!C2:C376,A34) -> 0 | C34: =SUMIF(Sites_Raw!C2:C376,A34,Sites_Raw!F2:F376) -> 0 | D34: =COUNTIFS(Sites_Raw!C2:C376,A34,Sites_Raw!G2:G376,"Active") -> 0
A35: Japan | B35: =COUNTIF(Sites_Raw!C2:C376,A35) -> 0 | C35: =SUMIF(Sites_Raw!C2:C376,A35,Sites_Raw!F2:F376) -> 0 | D35: =COUNTIFS(Sites_Raw!C2:C376,A35,Sites_Raw!G2:G376,"Active") -> 0
A36: South Africa | B36: =COUNTIF(Sites_Raw!C2:C376,A36) -> 0 | C36: =SUMIF(Sites_Raw!C2:C376,A36,Sites_Raw!F2:F376) -> 0 | D36: =COUNTIFS(Sites_Raw!C2:C376,A36,Sites_Raw!G2:G376,"Active") -> 0
A37: Spain | B37: =COUNTIF(Sites_Raw!C2:C376,A37) -> 0 | C37: =SUMIF(Sites_Raw!C2:C376,A37,Sites_Raw!F2:F376) -> 0 | D37: =COUNTIFS(Sites_Raw!C2:C376,A37,Sites_Raw!G2:G376,"Active") -> 0
A38: United Kingdom | B38: =COUNTIF(Sites_Raw!C2:C376,A38) -> 0 | C38: =SUMIF(Sites_Raw!C2:C376,A38,Sites_Raw!F2:F376) -> 0 | D38: =COUNTIFS(Sites_Raw!C2:C376,A38,Sites_Raw!G2:G376,"Active") -> 0
A39: United States | B39: =COUNTIF(Sites_Raw!C2:C376,A39) -> 0 | C39: =SUMIF(Sites_Raw!C2:C376,A39,Sites_Raw!F2:F376) -> 0 | D39: =COUNTIFS(Sites_Raw!C2:C376,A39,Sites_Raw!G2:G376,"Active") -> 0
A42: Adverse Event Outcomes (Serious events only)
A43: Outcome | B43: # Events
A44: Fatal | B44: =COUNTIFS(AE_Raw!F2:F501,"Severe",AE_Raw!G2:G501,"Serious",AE_Raw!J2:J501,A44) -> 0
A45: Ongoing | B45: =COUNTIFS(AE_Raw!F2:F501,"Severe",AE_Raw!G2:G501,"Serious",AE_Raw!J2:J501,A45) -> 0
A46: Resolved | B46: =COUNTIFS(AE_Raw!F2:F501,"Severe",AE_Raw!G2:G501,"Serious",AE_Raw!J2:J501,A46) -> 0
A47: Resolved with Sequelae | B47: =COUNTIFS(AE_Raw!F2:F501,"Severe",AE_Raw!G2:G501,"Serious",AE_Raw!J2:J501,A47) -> 0
A48: Resolving | B48: =COUNTIFS(AE_Raw!F2:F501,"Severe",AE_Raw!G2:G501,"Serious",AE_Raw!J2:J501,A48) -> 0

Sheet Agent_Logs_Raw
A1: log_id | B1: session_id | C1: timestamp | D1: user_role | E1: user_query | F1: agent_invoked | G1: tool_called | H1: response_summary | I1: latency_ms | J1: tokens_used | K1: feedback_rating | L1: escalated_flag
A2: LOG-00001 | B2: SESS-1441 | C2: 2026-06-28 10:04:00 | D2: Medical Science Liaison | E2: What did the latest literature review say about PD-1 inhibitors? | F2: Adverse Event Triage Agent | G2: vector_search_tool | H2: Classified event severity and logged to review queue. | I2: 1210 | J2: 2270 | K2: 4 | L2: =FALSE() -> FALSE
A3: LOG-00002 | B3: SESS-1664 | C3: 2026-08-07 07:35:00 | D3: Data Scientist | E3: Which Phase II trials for Cardiology are currently below 60% enrollment? | F3: Adverse Event Triage Agent | G3: ae_severity_classifier_tool | H3: No matching records found; suggested a broader query. | I3: 885 | J3: 5260 | K3: 5 | L3: =TRUE() -> TRUE
A4: LOG-00003 | B4: SESS-1412 | C4: 2026-07-05 11:43:00 | D4: Clinical Operations Manager | E4: Is there a hERG cardiotoxicity risk flagged for SNF-1121? | F4: Trial Data Analyst Agent | G4: ae_severity_classifier_tool | H4: Compiled multi-agent outputs into a one-page report. | I4: 730 | J4: 3687 | K4: 4 | L4: =FALSE() -> FALSE
A5: LOG-00004 | B5: SESS-1531 | C5: 2026-08-29 20:38:00 | D5: Data Scientist | E5: Draft a status report for TRL-0010 for the portfolio committee. | F5: Compound Similarity Agent | G5: citation_formatter_tool | H5: Returned structured table with 3 matching records. | I5: 970 | J5: 5626 | K5: 5 | L5: =FALSE() -> FALSE
A6: LOG-00005 | B6: SESS-1224 | C6: 2026-06-21 05:19:00 | D6: Research Scientist | E6: Which Phase II trials for Respiratory are currently below 60% enrollment? | F6: Report Writer Agent | G6: vector_search_tool | H6: Returned structured table with 3 matching records. | I6: 1360 | J6: 5522 | K6: 3 | L6: =FALSE() -> FALSE
A7: LOG-00006 | B7: SESS-1067 | C7: 2026-07-14 11:11:00 | D7: Medical Science Liaison | E7: Which Phase II trials for Oncology are currently below 60% enrollment? | F7: Compound Similarity Agent | G7: ae_severity_classifier_tool | H7: Returned structured table with 3 matching records. | I7: 906 | J7: 779 | K7: 3 | L7: =FALSE() -> FALSE
A8: LOG-00007 | B8: SESS-1401 | C8: 2026-08-13 15:32:00 | D8: Data Scientist | E8: Draft a status report for TRL-0047 for the portfolio committee. | F8: Trial Data Analyst Agent | G8: citation_formatter_tool | H8: Returned structured table with 3 matching records. | I8: 1018 | J8: 3402 | K8: 4 | L8: =FALSE() -> FALSE
A9: LOG-00008 | B9: SESS-1507 | C9: 2026-07-19 20:04:00 | D9: Clinical Operations Manager | E9: Find compounds similar to PSA-1103 targeting SGLT2. | F9: Report Writer Agent | G9: statistics_tool | H9: Retrieved 4 supporting document excerpts and generated a cited summary. | I9: 1420 | J9: 4995 | K9: 3 | L9: =FALSE() -> FALSE
A10: LOG-00009 | B10: SESS-1722 | C10: 2026-07-23 10:15:00 | D10: Medical Science Liaison | E10: Find compounds similar to DKU-1074 targeting GLP-1R. | F10: Literature & Document Research Agent | G10: escalation_notifier_tool | H10: Classified event severity and logged to review queue. | I10: 1467 | J10: 4764 | K10: 5 | L10: =FALSE() -> FALSE
A11: LOG-00010 | B11: SESS-1929 | C11: 2026-08-31 14:41:00 | D11: Biostatistician | E11: Which Phase II trials for Cardiology are currently below 60% enrollment? | F11: Router / Planner Agent | G11: vector_search_tool | H11: Compiled multi-agent outputs into a one-page report. | I11: 2262 | J11: 4502 | K11: 4 | L11: =FALSE() -> FALSE
A12: LOG-00011 | B12: SESS-1174 | C12: 2026-07-14 10:32:00 | D12: Regulatory Affairs Specialist | E12: How many sites are actively recruiting for Respiratory programs? | F12: Report Writer Agent | G12: ae_severity_classifier_tool | H12: No matching records found; suggested a broader query. | I12: 2092 | J12: 4712 | K12: 5 | L12: =FALSE() -> FALSE
A13: LOG-00012 | B13: SESS-1921 | C13: 2026-07-31 11:12:00 | D13: Data Scientist | E13: Summarize the most recent safety signal review for AGN-1114. | F13: Trial Data Analyst Agent | G13: vector_search_tool | H13: Retrieved 4 supporting document excerpts and generated a cited summary. | I13: 1791 | J13: 4112 | K13: 4 | L13: =FALSE() -> FALSE
A14: LOG-00013 | B14: SESS-1342 | C14: 2026-08-17 21:37:00 | D14: Research Scientist | E14: Which Phase II trials for Respiratory are currently below 60% enrollment? | F14: Report Writer Agent | G14: compound_similarity_tool | H14: Retrieved 4 supporting document excerpts and generated a cited summary. | I14: 1079 | J14: 6431 | K14: 2 | L14: =FALSE() -> FALSE
A15: LOG-00014 | B15: SESS-1608 | C15: 2026-06-02 18:31:00 | D15: Regulatory Affairs Specialist | E15: Draft a status report for TRL-0033 for the portfolio committee. | F15: Router / Planner Agent | G15: vector_search_tool | H15: Computed similarity score and returned top 5 candidate compounds. | I15: 828 | J15: 3809 | K15: 4 | L15: =FALSE() -> FALSE
... A57: LOG-00056 | B57: SESS-1879 | C57: 2026-08-19 22:35:00 | D57: Biostatistician | E57: Draft a status report for TRL-0026 for the portfolio committee. | F57: Compound Similarity Agent | G57: escalation_notifier_tool | H57: Compiled multi-agent outputs into a one-page report. | I57: 1612 | J57: 6315 | K57: 5 | L57: =FALSE() -> FALSE
A58: LOG-00057 | B58: SESS-1838 | C58: 2026-06-04 22:37:00 | D58: Biostatistician | E58: Summarize the most recent safety signal review for DKU-1061. | F58: Adverse Event Triage Agent | G58: vector_search_tool | H58: No matching records found; suggested a broader query. | I58: 1663 | J58: 5283 | K58: 4 | L58: =TRUE() -> TRUE
A59: LOG-00058 | B59: SESS-1205 | C59: 2026-09-08 12:29:00 | D59: Data Scientist | E59: Find compounds similar to AGN-1043 targeting VEGFR2. | F59: Trial Data Analyst Agent | G59: citation_formatter_tool | H59: Computed similarity score and returned top 5 candidate compounds. | I59: 2560 | J59: 2123 | K59: 5 | L59: =FALSE() -> FALSE
A60: LOG-00059 | B60: SESS-1982 | C60: 2026-06-19 04:59:00 | D60: Medical Science Liaison | E60: Draft a status report for TRL-0089 for the portfolio committee. | F60: Literature & Document Research Agent | G60: escalation_notifier_tool | H60: Computed similarity score and returned top 5 candidate compounds. | I60: 1178 | J60: 4396 | K60: 4 | L60: =FALSE() -> FALSE
A61: LOG-00060 | B61: SESS-1395 | C61: 2026-08-11 05:07:00 | D61: Biostatistician | E61: What did the latest literature review say about IL-6R inhibitors? | F61: Report Writer Agent | G61: ae_severity_classifier_tool | H61: Returned structured table with 3 matching records. | I61: 1543 | J61: 2679 | K61: 5 | L61: =FALSE() -> FALSE
A62: LOG-00061 | B62: SESS-1290 | C62: 2026-08-17 08:07:00 | D62: Data Scientist | E62: How many sites are actively recruiting for Infectious Disease programs? | F62: Adverse Event Triage Agent | G62: statistics_tool | H62: Returned structured table with 3 matching records. | I62: 1156 | J62: 3570 | K62: 3 | L62: =TRUE() -> TRUE
A63: LOG-00062 | B63: SESS-1666 | C63: 2026-07-26 02:47:00 | D63: Biostatistician | E63: Escalate any serious adverse events for TRL-0087 to the safety team. | F63: Adverse Event Triage Agent | G63: sql_query_tool | H63: Compiled multi-agent outputs into a one-page report. | I63: 1740 | J63: 2037 | K63: 3 | L63: =TRUE() -> TRUE
A64: LOG-00063 | B64: SESS-1479 | C64: 2026-06-26 08:37:00 | D64: Biostatistician | E64: How many sites are actively recruiting for Metabolic Disease programs? | F64: Router / Planner Agent | G64: ae_severity_classifier_tool | H64: Computed similarity score and returned top 5 candidate compounds. | I64: 1392 | J64: 2868 | K64: 5 | L64: =FALSE() -> FALSE
A65: LOG-00064 | B65: SESS-1512 | C65: 2026-08-05 03:01:00 | D65: Medical Science Liaison | E65: Draft a status report for TRL-0018 for the portfolio committee. | F65: Router / Planner Agent | G65: vector_search_tool | H65: Retrieved 4 supporting document excerpts and generated a cited summary. | I65: 1469 | J65: 3038 | K65: 4 | L65: =FALSE() -> FALSE
A66: LOG-00065 | B66: SESS-1525 | C66: 2026-08-11 02:39:00 | D66: Research Scientist | E66: What did the latest literature review say about BTK inhibitors? | F66: Report Writer Agent | G66: citation_formatter_tool | H66: Retrieved 4 supporting document excerpts and generated a cited summary. | I66: 918 | J66: 2596 | K66: 5 | L66: =FALSE() -> FALSE
A67: LOG-00066 | B67: SESS-1470 | C67: 2026-08-01 18:23:00 | D67: Biostatistician | E67: What adverse events have been reported most frequently for Oncology trials this year? | F67: Literature & Document Research Agent | G67: escalation_notifier_tool | H67: Retrieved 4 supporting document excerpts and generated a cited summary. | I67: 1037 | J67: 3790 | K67: 3 | L67: =FALSE() -> FALSE
A68: LOG-00067 | B68: SESS-1069 | C68: 2026-08-11 17:06:00 | D68: Biostatistician | E68: Draft a status report for TRL-0063 for the portfolio committee. | F68: Report Writer Agent | G68: ae_severity_classifier_tool | H68: Computed similarity score and returned top 5 candidate compounds. | I68: 1422 | J68: 1439 | K68: 5 | L68: =FALSE() -> FALSE
A69: LOG-00068 | B69: SESS-1949 | C69: 2026-07-03 20:04:00 | D69: Medical Science Liaison | E69: Is there a hERG cardiotoxicity risk flagged for RX-1112? | F69: Adverse Event Triage Agent | G69: citation_formatter_tool | H69: No matching records found; suggested a broader query. | I69: 1106 | J69: 4649 | K69: 4 | L69: =FALSE() -> FALSE
A70: LOG-00069 | B70: SESS-1602 | C70: 2026-07-29 23:54:00 | D70: Medical Science Liaison | E70: Show me the lab results trend for DKU-1039 over the last 6 months. | F70: Literature & Document Research Agent | G70: vector_search_tool | H70: Classified event severity and logged to review queue. | I70: 818 | J70: 1988 | K70: 5 | L70: =FALSE() -> FALSE
A71: LOG-00070 | B71: SESS-1069 | C71: 2026-08-13 12:06:00 | D71: Research Scientist | E71: Escalate any serious adverse events for TRL-0047 to the safety team. | F71: Compound Similarity Agent | G71: statistics_tool | H71: Returned structured table with 3 matching records. | I71: 854 | J71: 3696 | K71: 5 | L71: =FALSE() -> FALSE
A72: LOG-00071 | B72: SESS-1511 | C72: 2026-06-20 08:05:00 | D72: Biostatistician | E72: What adverse events have been reported most frequently for Infectious Disease trials this year? | F72: Trial Data Analyst Agent | G72: sql_query_tool | H72: Computed similarity score and returned top 5 candidate compounds. | I72: 1710 | J72: 2730 | K72: 5 | L72: =FALSE() -> FALSE
A73: LOG-00072 | B73: SESS-1107 | C73: 2026-07-14 01:47:00 | D73: Clinical Operations Manager | E73: What did the latest literature review say about BCL-2 inhibitors? | F73: Trial Data Analyst Agent | G73: statistics_tool | H73: No matching records found; suggested a broader query. | I73: 1580 | J73: 5862 | K73: 3 | L73: =FALSE() -> FALSE
A74: LOG-00073 | B74: SESS-1117 | C74: 2026-06-12 06:33:00 | D74: Research Scientist | E74: Is there a hERG cardiotoxicity risk flagged for VLX-1042? | F74: Adverse Event Triage Agent | G74: sql_query_tool | H74: No matching records found; suggested a broader query. | I74: 1907 | J74: 904 | K74: 4 | L74: =FALSE() -> FALSE
A75: LOG-00074 | B75: SESS-1860 | C75: 2026-08-08 03:26:00 | D75: Research Scientist | E75: Summarize the most recent safety signal review for VLX-1000. | F75: Adverse Event Triage Agent | G75: statistics_tool | H75: Retrieved 4 supporting document excerpts and generated a cited summary. | I75: 802 | J75: 4674 | K75: 5 | L75: =FALSE() -> FALSE
... A88: LOG-00087 | B88: SESS-1559 | C88: 2026-06-11 07:29:00 | D88: Biostatistician | E88: Show me the lab results trend for DKU-1024 over the last 6 months. | F88: Literature & Document Research Agent | G88: compound_similarity_tool | H88: Returned structured table with 3 matching records. | I88: 1808 | J88: 6078 | K88: 2 | L88: =FALSE() -> FALSE
A89: LOG-00088 | B89: SESS-1431 | C89: 2026-06-06 10:58:00 | D89: Regulatory Affairs Specialist | E89: Escalate any serious adverse events for TRL-0064 to the safety team. | F89: Adverse Event Triage Agent | G89: ae_severity_classifier_tool | H89: Retrieved 4 supporting document excerpts and generated a cited summary. | I89: 656 | J89: 4181 | K89: 5 | L89: =TRUE() -> TRUE
A90: LOG-00089 | B90: SESS-1560 | C90: 2026-07-08 04:18:00 | D90: Biostatistician | E90: What did the latest literature review say about PCSK9 inhibitors? | F90: Router / Planner Agent | G90: vector_search_tool | H90: Classified event severity and logged to review queue. | I90: 725 | J90: 5576 | K90: 4 | L90: =FALSE() -> FALSE
A91: LOG-00090 | B91: SESS-1824 | C91: 2026-06-14 06:33:00 | D91: Medical Science Liaison | E91: Which Phase II trials for Infectious Disease are currently below 60% enrollment? | F91: Trial Data Analyst Agent | G91: compound_similarity_tool | H91: Compiled multi-agent outputs into a one-page report. | I91: 895 | J91: 514 | K91: 5 | L91: =FALSE() -> FALSE
A92: LOG-00091 | B92: SESS-1612 | C92: 2026-08-15 18:34:00 | D92: Biostatistician | E92: Which Phase II trials for Respiratory are currently below 60% enrollment? | F92: Literature & Document Research Agent | G92: sql_query_tool | H92: Compiled multi-agent outputs into a one-page report. | I92: 1061 | J92: 2345 | K92: 5 | L92: =FALSE() -> FALSE
A93: LOG-00092 | B93: SESS-1277 | C93: 2026-06-24 13:38:00 | D93: Biostatistician | E93: Summarize the most recent safety signal review for RX-1112. | F93: Compound Similarity Agent | G93: compound_similarity_tool | H93: Returned structured table with 3 matching records. | I93: 813 | J93: 5907 | K93: 5 | L93: =FALSE() -> FALSE
...

Sheet Trials_Raw
A1: trial_id | B1: compound_id | C1: trial_phase | D1: therapeutic_area | E1: sponsor | F1: start_date | G1: planned_end_date | H1: actual_end_date | I1: status | J1: target_enrollment | K1: actual_enrollment | L1: primary_endpoint
A2: TRL-0001 | B2: CMP-0002 | C2: Phase III | D2: Metabolic Disease | E2: PharmaSense Global R&D | F2: 2024-02-01 | G2: 2025-03-08 | H2: 2025-03-08 | I2: Completed | J2: 525 | K2: 511 | L2: Reduction in LDL Cholesterol
A3: TRL-0002 | B3: CMP-0005 | C3: Phase II | D3: Infectious Disease | E3: PharmaSense Oncology Division | F3: 2025-07-19 | G3: 2026-08-01 | H3: 2026-08-01 | I3: Completed | J3: 333 | K3: 293 | L3: Time to Symptom Resolution
A4: TRL-0003 | B4: CMP-0006 | C4: Phase I | D4: Respiratory | E4: PharmaSense Oncology Division | F4: 2022-02-28 | G4: 2023-07-02 | H4: 2022-06-12 | I4: Terminated | J4: 44 | K4: 23 | L4: Reduction in LDL Cholesterol
A5: TRL-0004 | B5: CMP-0007 | C5: Phase I | D5: Cardiology | E5: PharmaSense Global R&D | F5: 2022-10-13 | G5: 2023-06-05 | H5: 2023-06-05 | I5: Completed | J5: 596 | K5: 521 | L5: Change in HbA1c from Baseline
A6: TRL-0005 | B6: CMP-0012 | C6: Phase II | D6: Metabolic Disease | E6: PharmaSense Global R&D | F6: 2025-01-21 | G6: 2025-11-02 | I6: Active, not recruiting | J6: 42 | K6: 31 | L6: Objective Response Rate (ORR)
A7: TRL-0006 | B7: CMP-0012 | C7: Phase II | D7: Metabolic Disease | E7: PharmaSense Global R&D | F7: 2023-03-12 | G7: 2025-01-10 | I7: Recruiting | J7: 481 | K7: 391 | L7: Change in HbA1c from Baseline
A8: TRL-0007 | B8: CMP-0015 | C8: Phase II | D8: Cardiology | E8: PharmaSense Therapeutics | F8: 2024-07-10 | G8: 2025-09-21 | H8: 2025-09-21 | I8: Completed | J8: 519 | K8: 493 | L8: Progression-Free Survival (PFS)
A9: TRL-0008 | B9: CMP-0017 | C9: Phase I | D9: Infectious Disease | E9: PharmaSense Therapeutics | F9: 2024-01-01 | G9: 2025-11-14 | I9: Recruiting | J9: 105 | K9: 43 | L9: Change in HbA1c from Baseline
A10: TRL-0009 | B10: CMP-0017 | C10: Phase I | D10: Infectious Disease | E10: PharmaSense Therapeutics | F10: 2024-04-12 | G10: 2025-03-10 | H10: 2025-03-10 | I10: Completed | J10: 341 | K10: 356 | L10: ACR20 Response Rate
A11: TRL-0010 | B11: CMP-0018 | C11: Phase II | D11: Oncology | E11: PharmaSense Oncology Division | F11: 2023-10-08 | G11: 2025-10-28 | H11: 2025-10-28 | I11: Completed | J11: 456 | K11: 411 | L11: Safety and Tolerability (MTD)
A12: TRL-0011 | B12: CMP-0019 | C12: Phase II | D12: Infectious Disease | E12: PharmaSense Neuroscience Unit | F12: 2025-04-27 | G12: 2027-01-20 | H12: 2027-01-20 | I12: Completed | J12: 334 | K12: 319 | L12: Reduction in LDL Cholesterol
A13: TRL-0012 | B13: CMP-0019 | C13: Phase II | D13: Infectious Disease | E13: PharmaSense Therapeutics | F13: 2023-04-24 | G13: 2025-05-25 | H13: 2025-05-25 | I13: Completed | J13: 91 | K13: 79 | L13: ACR20 Response Rate
A14: TRL-0013 | B14: CMP-0020 | C14: Phase I | D14: Metabolic Disease | E14: PharmaSense Oncology Division | F14: 2025-02-09 | G14: 2026-05-05 | H14: 2026-05-05 | I14: Completed | J14: 113 | K14: 108 | L14: ACR20 Response Rate
A15: TRL-0014 | B15: CMP-0023 | C15: Phase II | D15: Infectious Disease | E15: PharmaSense Oncology Division | F15: 2023-01-08 | G15: 2025-01-22 | I15: Suspended | J15: 106 | K15: 48 | L15: Overall Survival (OS)
A16: TRL-0015 | B16: CMP-0024 | C16: Phase III | D16: Metabolic Disease | E16: PharmaSense Global R&D | F16: 2022-12-05 | G16: 2024-09-06 | H16: 2024-09-06 | I16: Completed | J16: 511 | K16: 529 | L16: Overall Survival (OS)
A17: TRL-0016 | B17: CMP-0024 | C17: Phase III | D17: Metabolic Disease | E17: PharmaSense Global R&D | F17: 2022-04-18 | G17: 2023-06-09 | I17: Recruiting | J17: 325 | K17: 293 | L17: Objective Response Rate (ORR)
A18: TRL-0017 | B18: CMP-0026 | C18: Phase IV | D18: Respiratory | E18: PharmaSense Oncology Division | F18: 2022-08-23 | G18: 2025-01-22 | H18: 2025-01-22 | I18: Completed | J18: 269 | K18: 232 | L18: Safety and Tolerability (MTD)
A19: TRL-0018 | B19: CMP-0027 | C19: Phase II | D19: Cardiology | E19: PharmaSense Oncology Division | F19: 2022-04-16 | G19: 2024-04-22 | I19: Active, not recruiting | J19: 260 | K19: 190 | L19: Reduction in LDL Cholesterol
A20: TRL-0019 | B20: CMP-0029 | C20: Phase II | D20: Oncology | E20: PharmaSense Oncology Division | F20: 2024-04-20 | G20: 2024-12-29 | I20: Recruiting | J20: 91 | K20: 57 | L20: Reduction in LDL Cholesterol
A21: TRL-0020 | B21: CMP-0032 | C21: Phase IV | D21: Respiratory | E21: PharmaSense Global R&D | F21: 2025-05-25 | G21: 2027-02-13 | I21: Active, not recruiting | J21: 157 | K21: 104 | L21: Safety and Tolerability (MTD)
A22: TRL-0021 | B22: CMP-0034 | C22: Phase II | D22: Neurology | E22: PharmaSense Neuroscience Unit | F22: 2022-08-10 | G22: 2024-07-02 | I22: Recruiting | J22: 582 | K22: 496 | L22: Objective Response Rate (ORR)
A23: TRL-0022 | B23: CMP-0035 | C23: Phase II | D23: Infectious Disease | E23: PharmaSense Neuroscience Unit | F23: 2022-10-04 | G23: 2024-12-04 | I23: Suspended | J23: 70 | K23: 64 | L23: Time to Symptom Resolution
A24: TRL-0023 | B24: CMP-0036 | C24: Phase III | D24: Metabolic Disease | E24: PharmaSense Therapeutics | F24: 2024-01-20 | G24: 2024-08-13 | H24: 2024-08-13 | I24: Completed | J24: 123 | K24: 107 | L24: Reduction in LDL Cholesterol
A25: TRL-0024 | B25: CMP-0037 | C25: Phase IV | D25: Cardiology | E25: PharmaSense Global R&D | F25: 2025-03-20 | G25: 2026-03-14 | H25: 2026-03-14 | I25: Completed | J25: 511 | K25: 436 | L25: Change in HbA1c from Baseline
A26: TRL-0025 | B26: CMP-0038 | C26: Phase I | D26: Neurology | E26: PharmaSense Therapeutics | F26: 2026-06-08 | G26: 2028-09-15 | I26: Recruiting | J26: 533 | K26: 235 | L26: Objective Response Rate (ORR)
A27: TRL-0026 | B27: CMP-0038 | C27: Phase I | D27: Neurology | E27: PharmaSense Global R&D | F27: 2024-04-01 | G27: 2025-09-19 | I27: Active, not recruiting | J27: 448 | K27: 348 | L27: Time to Symptom Resolution
A28: TRL-0027 | B28: CMP-0039 | C28: Phase III | D28: Neurology | E28: PharmaSense Neuroscience Unit | F28: 2023-01-30 | G28: 2024-01-09 | H28: 2024-01-09 | I28: Completed | J28: 367 | K28: 344 | L28: Objective Response Rate (ORR)
A29: TRL-0028 | B29: CMP-0040 | C29: Phase III | D29: Metabolic Disease | E29: PharmaSense Neuroscience Unit | F29: 2022-03-13 | G29: 2024-07-18 | I29: Active, not recruiting | J29: 440 | K29: 417 | L29: Progression-Free Survival (PFS)
A30: TRL-0029 | B30: CMP-0043 | C30: Phase I | D30: Infectious Disease | E30: PharmaSense Therapeutics | F30: 2022-08-26 | G30: 2023-11-07 | I30: Active, not recruiting | J30: 361 | K30: 194 | L30: Safety and Tolerability (MTD)
A31: TRL-0030 | B31: CMP-0045 | C31: Phase I | D31: Immunology | E31: PharmaSense Neuroscience Unit | F31: 2022-10-23 | G31: 2025-02-22 | I31: Recruiting | J31: 585 | K31: 465 | L31: Safety and Tolerability (MTD)
A32: TRL-0031 | B32: CMP-0048 | C32: Phase II | D32: Neurology | E32: PharmaSense Global R&D | F32: 2022-07-31 | G32: 2023-08-07 | H32: 2023-08-07 | I32: Completed | J32: 560 | K32: 500 | L32: Objective Response Rate (ORR)
A33: TRL-0032 | B33: CMP-0051 | C33: Phase II | D33: Neurology | E33: PharmaSense Global R&D | F33: 2021-10-12 | G33: 2022-06-01 | I33: Recruiting | J33: 238 | K33: 169 | L33: Change in HbA1c from Baseline
A34: TRL-0033 | B34: CMP-0051 | C34: Phase II | D34: Neurology | E34: PharmaSense Neuroscience Unit | F34: 2024-04-17 | G34: 2025-08-04 | H34: 2025-08-04 | I34: Completed | J34: 478 | K34: 432 | L34: Progression-Free Survival (PFS)
A35: TRL-0034 | B35: CMP-0052 | C35: Phase I | D35: Respiratory | E35: PharmaSense Oncology Division | F35: 2023-01-14 | G35: 2025-04-18 | I35: Suspended | J35: 275 | K35: 86 | L35: Reduction in LDL Cholesterol
A36: TRL-0035 | B36: CMP-0053 | C36: Phase II | D36: Respiratory | E36: PharmaSense Therapeutics | F36: 2026-06-04 | G36: 2028-06-18 | I36: Active, not recruiting | J36: 447 | K36: 405 | L36: ACR20 Response Rate
A37: TRL-0036 | B37: CMP-0054 | C37: Phase III | D37: Neurology | E37: PharmaSense Neuroscience Unit | F37: 2024-05-21 | G37: 2026-03-04 | I37: Active, not recruiting | J37: 150 | K37: 101 | L37: Reduction in LDL Cholesterol
A38: TRL-0037 | B38: CMP-0055 | C38: Phase II | D38: Oncology | E38: PharmaSense Neuroscience Unit | F38: 2025-01-31 | G38: 2026-09-28 | I38: Active, not recruiting | J38: 524 | K38: 212 | L38: ACR20 Response Rate
A39: TRL-0038 | B39: CMP-0056 | C39: Phase III | D39: Oncology | E39: PharmaSense Neuroscience Unit | F39: 2022-04-28 | G39: 2024-05-11 | I39: Suspended | J39: 178 | K39: 90 | L39: ACR20 Response Rate
A40: TRL-0039 | B40: CMP-0056 | C40: Phase III | D40: Oncology | E40: PharmaSense Oncology Division | F40: 2025-11-29 | G40: 2028-01-31 | H40: 2026-07-30 | I40: Terminated | J40: 550 | K40: 118 | L40: Progression-Free Survival (PFS)
...

Sheet AE_Raw
A1: event_id | B1: trial_id | C1: site_id | D1: patient_code | E1: event_date | F1: adverse_event_term | G1: severity | H1: seriousness | I1: causality_assessment | J1: outcome | K1: reported_by
A2: AE-00001 | B2: TRL-0056 | C2: SITE-00193 | D2: PT-77302 | E2: 2023-09-04 | F2: Cough | G2: Mild | H2: Non-serious | I2: Related | J2: Resolving | K2: Dr. Oconnor
A3: AE-00002 | B3: TRL-0002 | C3: SITE-00003 | D3: PT-25587 | E3: 2026-03-26 | F3: Insomnia | G3: Mild | H3: Non-serious | I3: Related | J3: Resolved | K3: Dr. Cox
A4: AE-00003 | B4: TRL-0097 | C4: SITE-00333 | D4: PT-49537 | E4: 2024-02-13 | F4: Headache | G4: Mild | H4: Non-serious | I4: Related | J4: Resolved | K4: Dr. Wagner
A5: AE-00004 | B5: TRL-0043 | C5: SITE-00153 | D5: PT-88878 | E5: 2026-05-15 | F5: Diarrhea | G5: Moderate | H5: Non-serious | I5: Possibly Related | J5: Resolved | K5: Dr. Valdez
A6: AE-00005 | B6: TRL-0093 | C6: SITE-00320 | D6: PT-97896 | E6: 2025-02-17 | F6: Dizziness | G6: Moderate | H6: Non-serious | I6: Related | J6: Resolved | K6: Dr. Cole
A7: AE-00006 | B7: TRL-0097 | C7: SITE-00332 | D7: PT-29078 | E7: 2024-05-21 | F7: Insomnia | G7: Moderate | H7: Non-serious | I7: Unlikely Related | J7: Resolving | K7: Dr. Hudson
A8: AE-00007 | B8: TRL-0096 | C8: SITE-00330 | D8: PT-31044 | E8: 2026-01-07 | F8: Decreased Appetite | G8: Moderate | H8: Non-serious | I8: Possibly Related | J8: Ongoing | K8: Dr. Martinez
A9: AE-00008 | B9: TRL-0059 | C9: SITE-00203 | D9: PT-84741 | E9: 2024-11-10 | F9: Fatigue | G9: Mild | H9: Non-serious | I9: Related | J9: Ongoing | K9: Dr. Frank
A10: AE-00009 | B10: TRL-0088 | C10: SITE-00305 | D10: PT-11832 | E10: 2024-05-05 | F10: Decreased Appetite | G10: Moderate | H10: Non-serious | I10: Possibly Related | J10: Ongoing | K10: Dr. Richards
A11: AE-00010 | B11: TRL-0078 | C11: SITE-00268 | D11: PT-35106 | E11: 2023-04-07 | F11: Peripheral Neuropathy | G11: Mild | H11: Non-serious | I11: Possibly Related | J11: Ongoing | K11: Dr. Green
A12: AE-00011 | B12: TRL-0091 | C12: SITE-00313 | D12: PT-22934 | E12: 2023-11-10 | F12: Diarrhea | G12: Severe | H12: Non-serious | I12: Not Related | J12: Resolving | K12: Dr. Edwards
... A501: AE-00500 | B501: TRL-0038 | C501: SITE-00137 | D501: PT-26272 | E501: 2025-11-24 | F501: Myalgia | G501: Mild | H501: Non-serious | I501: Not Related | J501: Resolved | K501: Dr. Kaufman

Sheet Sites_Raw
A1: site_id | B1: trial_id | C1: site_name | D1: country | E1: principal_investigator | F1: enrollment_count | G1: site_status
A2: SITE-00001 | B2: TRL-0001 | C2: South Jessicaview Medical Center | D2: India | E2: Dr. Johnson | F2: 375 | G2: Pending Activation
A3: SITE-00002 | B3: TRL-0001 | C3: Lake Mary Community Health Network | D3: United Kingdom | E3: Dr. Johnston | F3: 193 | G3: Closed
A4: SITE-00003 | B4: TRL-0002 | C4: Port Emilyview Regional Cancer Center | D4: Brazil | E4: Dr. Johnston | F4: 84 | G4: Active
A5: SITE-00004 | B5: TRL-0002 | C5: South April University Hospital | D5: Japan | E5: Dr. Ramos | F5: 60 | G5: Pending Activation
A6: SITE-00005 | B6: TRL-0002 | C6: Howardshire University Hospital | D6: Spain | E6: Dr. Graham | F6: 93 | G6: Pending Activation
A7: SITE-00006 | B7: TRL-0002 | C7: Costafort Medical Center | D7: United States | E7: Dr. Bailey | F7: 46 | G7: Active
A8: SITE-00007 | B8: TRL-0003 | C8: Manuelville Community Health Network | D8: United States | E8: Dr. Hodge | F8: 16 | G8: Pending Activation
A9: SITE-00008 | B9: TRL-0003 | C9: Robertfort Medical Center | D9: Japan | E9: Dr. Roberts | F9: 10 | G9: Closed
A10: SITE-00009 | B10: TRL-0004 | C10: Cervantesside Regional Cancer Center | D10: Australia | E10: Dr. Johnson | F10: 63 | G10: Pending Activation
A11: SITE-00010 | B11: TRL-0004 | C11: West Johnnyville Regional Cancer Center | D11: Canada | E11: Dr. Cordova | F11: 49 | G11: Closed
A12: SITE-00011 | B12: TRL-0004 | C12: Hancocktown Clinical Research Institute | D12: South Africa | E12: Dr. Sandoval | F12: 58 | G12: Active
A13: SITE-00012 | B13: TRL-0004 | C13: Gutierrezborough University Hospital | D13: Canada | E13: Dr. Stone | F13: 88 | G13: Active
... A376: SITE-00375 | B376: TRL-0110 | C376: Rhodesside Community Health Network | D376: United Kingdom | E376: Dr. Rivera | F376: 31 | G376: Closed
